Workbook

Sheet Summary
A1: Blockmancer Release 1.0 Visual Asset Checklist — 627 Source Update
A2: Separated from audio/SFX. Visual source contract: board blocks remain 24x24 / board icons 48x48; all non-board visual assets may use 627x627 source or 1254x1254 2x2 sheets with category-constrained runtime display.
A4: Category Sheet | B4: Original Category | C4: Total Assets | D4: Done | E4: Remaining | F4: Progress
A5: 00 Global Placeholder | B5: 0. Global Placeholder Assets — Visual | C5: =COUNTA('00 Global Placeholder'!$B$5:$B$10000) | D5: =COUNTIF('00 Global Placeholder'!$A$5:$A$10000,"☑") | E5: =C5-D5 | F5: =IFERROR(D5/C5,0)
A6: 08 BG - Scenes | B6: 8. Background Assets — Scenes | C6: =COUNTA('08 BG - Scenes'!$B$5:$B$10000) | D6: =COUNTIF('08 BG - Scenes'!$A$5:$A$10000,"☑") | E6: =C6-D6 | F6: =IFERROR(D6/C6,0)
A7: 09 BG - Stage Battle Parallax | B7: 9. Background Assets — Stage Battle Parallax | C7: =COUNTA('09 BG - Stage Battle Parallax'!$B$5:$B$10000) | D7: =COUNTIF('09 BG - Stage Battle Parallax'!$A$5:$A$10000,"☑") | E7: =C7-D7 | F7: =IFERROR(D7/C7,0)
A8: 10 BG - Boss Arenas | B8: 10. Background Assets — Boss Arenas | C8: =COUNTA('10 BG - Boss Arenas'!$B$5:$B$10000) | D8: =COUNTIF('10 BG - Boss Arenas'!$A$5:$A$10000,"☑") | E8: =C8-D8 | F8: =IFERROR(D8/C8,0)
A9: 11 Map - Map BGs | B9: 11. Map Assets — Map Backgrounds | C9: =COUNTA('11 Map - Map BGs'!$B$5:$B$10000) | D9: =COUNTIF('11 Map - Map BGs'!$A$5:$A$10000,"☑") | E9: =C9-D9 | F9: =IFERROR(D9/C9,0)
A10: 12 Map - Node States | B10: 12. Map Assets — Node States | C10: =COUNTA('12 Map - Node States'!$B$5:$B$10000) | D10: =COUNTIF('12 Map - Node States'!$A$5:$A$10000,"☑") | E10: =C10-D10 | F10: =IFERROR(D10/C10,0)
A11: 13 Map - Paths and Decorations | B11: 13. Map Assets — Paths and Decorations | C11: =COUNTA('13 Map - Paths and Decorations'!$B$5:$B$10000) | D11: =COUNTIF('13 Map - Paths and Decorations'!$A$5:$A$10000,"☑") | E11: =C11-D11 | F11: =IFERROR(D11/C11,0)
A12: 14 - Heroes | B12: 14. Sprite Assets — Playable Heroes | C12: =COUNTA('14 - Heroes'!$B$5:$B$10000) | D12: =COUNTIF('14 - Heroes'!$A$5:$A$10000,"☑") | E12: =C12-D12 | F12: =IFERROR(D12/C12,0)
A13: 15 - Monsters | B13: 15. Sprite Assets — Regular Monsters | C13: =COUNTA('15 - Monsters'!$B$5:$B$10000) | D13: =COUNTIF('15 - Monsters'!$A$5:$A$10000,"☑") | E13: =C13-D13 | F13: =IFERROR(D13/C13,0)
A14: 16 - Bosses | B14: 16. Sprite Assets — Bosses | C14: =COUNTA('16 - Bosses'!$B$5:$B$10000) | D14: =COUNTIF('16 - Bosses'!$A$5:$A$10000,"☑") | E14: =C14-D14 | F14: =IFERROR(D14/C14,0)
A15: 17 - NPCs | B15: 17. Sprite Assets — NPCs | C15: =COUNTA('17 - NPCs'!$B$5:$B$10000) | D15: =COUNTIF('17 - NPCs'!$A$5:$A$10000,"☑") | E15: =C15-D15 | F15: =IFERROR(D15/C15,0)
A16: 18 - Board Blocks | B16: 18. Runtime Sprite Assets — Board Blocks and Board UI | C16: =COUNTA('18 - Board Blocks'!$B$5:$B$10000) | D16: =COUNTIF('18 - Board Blocks'!$A$5:$A$10000,"☑") | E16: =C16-D16 | F16: =IFERROR(D16/C16,0)
A17: 19 and VFX - Spells | B17: 19. Icon and VFX Assets — Spells | C17: =COUNTA('19 and VFX - Spells'!$B$5:$B$10000) | D17: =COUNTIF('19 and VFX - Spells'!$A$5:$A$10000,"☑") | E17: =C17-D17 | F17: =IFERROR(D17/C17,0)
A18: 20 - Items | B18: 20. Icon Assets — Items and Reactive Counter Items | C18: =COUNTA('20 - Items'!$B$5:$B$10000) | D18: =COUNTIF('20 - Items'!$A$5:$A$10000,"☑") | E18: =C18-D18 | F18: =IFERROR(D18/C18,0)
A19: 21 - Relics | B19: 21. Icon Assets — Relics | C19: =COUNTA('21 - Relics'!$B$5:$B$10000) | D19: =COUNTIF('21 - Relics'!$A$5:$A$10000,"☑") | E19: =C19-D19 | F19: =IFERROR(D19/C19,0)
A20: 22 - Upgrades | B20: 22. Icon Assets — Upgrades | C20: =COUNTA('22 - Upgrades'!$B$5:$B$10000) | D20: =COUNTIF('22 - Upgrades'!$A$5:$A$10000,"☑") | E20: =C20-D20 | F20: =IFERROR(D20/C20,0)
A21: 23 and - Weapons | B21: 23. Icon and Sprite Assets — Weapons | C21: =COUNTA('23 and - Weapons'!$B$5:$B$10000) | D21: =COUNTIF('23 and - Weapons'!$A$5:$A$10000,"☑") | E21: =C21-D21 | F21: =IFERROR(D21/C21,0)
A22: 24 - Status Effects | B22: 24. Icon Assets — Status Effects | C22: =COUNTA('24 - Status Effects'!$B$5:$B$10000) | D22: =COUNTIF('24 - Status Effects'!$A$5:$A$10000,"☑") | E22: =C22-D22 | F22: =IFERROR(D22/C22,0)
A23: 25 - Oopsies | B23: 25. Icon Assets — Oopsies / Silly Drawbacks | C23: =COUNTA('25 - Oopsies'!$B$5:$B$10000) | D23: =COUNTIF('25 - Oopsies'!$A$5:$A$10000,"☑") | E23: =C23-D23 | F23: =IFERROR(D23/C23,0)
A24: 26 - Festival Chaos Rules | B24: 26. Icon Assets — Festival Chaos Rules | C24: =COUNTA('26 - Festival Chaos Rules'!$B$5:$B$10000) | D24: =COUNTIF('26 - Festival Chaos Rules'!$A$5:$A$10000,"☑") | E24: =C24-D24 | F24: =IFERROR(D24/C24,0)
A25: 27 - Battle Objectives | B25: 27. Icon Assets — Battle Objectives | C25: =COUNTA('27 - Battle Objectives'!$B$5:$B$10000) | D25: =COUNTIF('27 - Battle Objectives'!$A$5:$A$10000,"☑") | E25: =C25-D25 | F25: =IFERROR(D25/C25,0)
A26: 28 - Events | B26: 28. Icon Assets — Room Events and Random Gameplay Events | C26: =COUNTA('28 - Events'!$B$5:$B$10000) | D26: =COUNTIF('28 - Events'!$A$5:$A$10000,"☑") | E26: =C26-D26 | F26: =IFERROR(D26/C26,0)
A27: 29 - Boss Rule Cards | B27: 29. Icon Assets — Boss Rule Cards | C27: =COUNTA('29 - Boss Rule Cards'!$B$5:$B$10000) | D27: =COUNTIF('29 - Boss Rule Cards'!$A$5:$A$10000,"☑") | E27: =C27-D27 | F27: =IFERROR(D27/C27,0)
A28: 30 - Currency Collect | B28: 30. Icon Assets — Currencies and Collectibles | C28: =COUNTA('30 - Currency Collect'!$B$5:$B$10000) | D28: =COUNTIF('30 - Currency Collect'!$A$5:$A$10000,"☑") | E28: =C28-D28 | F28: =IFERROR(D28/C28,0)
A29: 31 and - Hub Buildings | B29: 31. Sprite and Icon Assets — Festival Hub Buildings | C29: =COUNTA('31 and - Hub Buildings'!$B$5:$B$10000) | D29: =COUNTIF('31 and - Hub Buildings'!$A$5:$A$10000,"☑") | E29: =C29-D29 | F29: =IFERROR(D29/C29,0)
A30: 32 UI - Panels Frames | B30: 32. UI Assets — Panels and Frames | C30: =COUNTA('32 UI - Panels Frames'!$B$5:$B$10000) | D30: =COUNTIF('32 UI - Panels Frames'!$A$5:$A$10000,"☑") | E30: =C30-D30 | F30: =IFERROR(D30/C30,0)
A31: 33 UI - Buttons | B31: 33. UI Assets — Buttons | C31: =COUNTA('33 UI - Buttons'!$B$5:$B$10000) | D31: =COUNTIF('33 UI - Buttons'!$A$5:$A$10000,"☑") | E31: =C31-D31 | F31: =IFERROR(D31/C31,0)
A32: 34 UI - Controls | B32: 34. UI Assets — Mobile Controls | C32: =COUNTA('34 UI - Controls'!$B$5:$B$10000) | D32: =COUNTIF('34 UI - Controls'!$A$5:$A$10000,"☑") | E32: =C32-D32 | F32: =IFERROR(D32/C32,0)
A33: 35 UI - HUD | B33: 35. UI Assets — HUD and Meters | C33: =COUNTA('35 UI - HUD'!$B$5:$B$10000) | D33: =COUNTIF('35 UI - HUD'!$A$5:$A$10000,"☑") | E33: =C33-D33 | F33: =IFERROR(D33/C33,0)
A34: 36 VFX - VFX | B34: 36. VFX Assets — Board, Combat, and Status | C34: =COUNTA('36 VFX - VFX'!$B$5:$B$10000) | D34: =COUNTIF('36 VFX - VFX'!$A$5:$A$10000,"☑") | E34: =C34-D34 | F34: =IFERROR(D34/C34,0)
A35: 37 Font | B35: 37. Font Assets | C35: =COUNTA('37 Font'!$B$5:$B$10000) | D35: =COUNTIF('37 Font'!$A$5:$A$10000,"☑") | E35: =C35-D35 | F35: =IFERROR(D35/C35,0)
A36: 38 Store | B36: 38. Store and Platform Assets | C36: =COUNTA('38 Store'!$B$5:$B$10000) | D36: =COUNTIF('38 Store'!$A$5:$A$10000,"☑") | E36: =C36-D36 | F36: =IFERROR(D36/C36,0)
A37: Update Status | B37: Latest Workbook Update — Exact Runtime IDs + Folder Contract | C37: =COUNTA('Update Status'!$B$5:$B$10000) | D37: =COUNTIF('Update Status'!$A$5:$A$10000,"☑") | E37: =C37-D37 | F37: =IFERROR(D37/C37,0)
A38: Done vs Gaps | B38: Area | C38: =COUNTA('Done vs Gaps'!$B$5:$B$10000) | D38: =COUNTIF('Done vs Gaps'!$A$5:$A$10000,"☑") | E38: =C38-D38 | F38: =IFERROR(D38/C38,0)
A39: Asset Backlog | B39: Priority | C39: =COUNTA('Asset Backlog'!$B$5:$B$10000) | D39: =COUNTIF('Asset Backlog'!$A$5:$A$10000,"☑") | E39: =C39-D39 | F39: =IFERROR(D39/C39,0)
A40: Runtime Coverage | B40: Metric / Category | C40: =COUNTA('Runtime Coverage'!$B$5:$B$10000) | D40: =COUNTIF('Runtime Coverage'!$A$5:$A$10000,"☑") | E40: =C40-D40 | F40: =IFERROR(D40/C40,0)
A41: Animation Coverage | B41: Category | C41: =COUNTA('Animation Coverage'!$B$5:$B$10000) | D41: =COUNTIF('Animation Coverage'!$A$5:$A$10000,"☑") | E41: =C41-D41 | F41: =IFERROR(D41/C41,0)
...

Sheet 00 Global Placeholder
A1: 0. Global Placeholder Assets — Visual
A2: Visual fallbacks only. Audio fallback lives in the separate SFX workbook.
A4: Done? | B4: Asset Key | C4: Suggested Path | D4: Designer Description | E4: Priority | F4: Source / Export Size | G4: Runtime Render Size | H4: Exact Frames / Count | I4: Final Folder Structure (relative to public/assets) | J4: Audit / Release Note | K4: GDD Theme / Prompt Note
A5: ☐ | B5: missing_texture | C5: placeholders/missing_texture.png | D5: Generic fallback texture for missing non-board image assets. | E5: P0 fallback | F5: 627x627 PNG source | G5: HUD/button 24-48px; inventory 32-64px; reward/shop card 64-96px; modal 96-128px | H5: Static fallback | I5: placeholders/ | J5: Updated: missing assets must not crash runtime. | Updated 2026-05-19: non-board visual source supports 627x627 PNG or 1254x1254 2x2 sheets; runtime display is category-constrained. | K5: Friendly temporary art, not dark/debug-looking.
A6: ☐ | B6: missing_hero | C6: placeholders/missing_hero.png | D6: Simple friendly character silhouette for missing hero sheets. | E6: P0 fallback | F6: 627x627 PNG source | G6: HUD/button 24-48px; inventory 32-64px; reward/shop card 64-96px; modal 96-128px | H6: Static fallback | I6: placeholders/ | J6: Fallback for heroPoseSheet. | Updated 2026-05-19: non-board visual source supports 627x627 PNG or 1254x1254 2x2 sheets; runtime display is category-constrained. | K6: Cheerful placeholder silhouette.
A7: ☐ | B7: missing_monster | C7: placeholders/missing_monster.png | D7: Cute monster silhouette for missing monster sheets. | E7: P0 fallback | F7: 627x627 PNG source | G7: HUD/button 24-48px; inventory 32-64px; reward/shop card 64-96px; modal 96-128px | H7: Static fallback | I7: placeholders/ | J7: Fallback for monsterPoseSheet. | Updated 2026-05-19: non-board visual source supports 627x627 PNG or 1254x1254 2x2 sheets; runtime display is category-constrained. | K7: Cute-chaotic placeholder.
A8: ☐ | B8: missing_boss | C8: placeholders/missing_boss.png | D8: Readable large boss silhouette for missing boss sheets. | E8: P0 fallback | F8: 627x627 PNG source | G8: HUD/button 24-48px; inventory 32-64px; reward/shop card 64-96px; modal 96-128px | H8: Static fallback | I8: placeholders/ | J8: Fallback for bossPoseSheet. | Updated 2026-05-19: non-board visual source supports 627x627 PNG or 1254x1254 2x2 sheets; runtime display is category-constrained. | K8: Funny boss placeholder, not scary.
A9: ☐ | B9: missing_portrait | C9: placeholders/missing_portrait.png | D9: Portrait fallback for hero/NPC/boss dialogue. | E9: P0 fallback | F9: 627x627 PNG portrait source | G9: Dialogue 96-128px; story/unlock modal 128-220px; preserve aspect ratio | H9: Static fallback | I9: placeholders/ | J9: Fallback for portraitKey. | Updated 2026-05-19: non-board visual source supports 627x627 PNG or 1254x1254 2x2 sheets; runtime display is category-constrained. | K9: Friendly portrait placeholder.
A10: ☐ | B10: missing_icon | C10: placeholders/missing_icon.png | D10: Readable missing icon tile for items, spells, relics, upgrades, weapons, status, hazards. | E10: P0 fallback | F10: 627x627 PNG source | G10: HUD/button 24-48px; inventory 32-64px; reward/shop card 64-96px; modal 96-128px | H10: Static fallback | I10: placeholders/ | J10: Fallback for iconKey. | Updated 2026-05-19: non-board visual source supports 627x627 PNG or 1254x1254 2x2 sheets; runtime display is category-constrained. | K10: Cute question-rune icon.
A11: ☐ | B11: missing_vfx | C11: placeholders/missing_vfx.png | D11: Generic sparkle burst for missing VFX hooks. | E11: P0 fallback | F11: 627x627 PNG source | G11: HUD/button 24-48px; inventory 32-64px; reward/shop card 64-96px; modal 96-128px | H11: Static or 4-frame fallback | I11: placeholders/ | J11: Fallback for vfxKey. | Updated 2026-05-19: non-board visual source supports 627x627 PNG or 1254x1254 2x2 sheets; runtime display is category-constrained. | K11: Sparkly magical cleanup feedback.
A12: ☐ | B12: missing_map_icon | C12: placeholders/missing_map_icon.png | D12: Fallback icon for map/room nodes. | E12: P0 fallback | F12: 627x627 PNG source | G12: HUD/button 24-48px; inventory 32-64px; reward/shop card 64-96px; modal 96-128px | H12: Static fallback | I12: placeholders/ | J12: Fallback for map icons. | Updated 2026-05-19: non-board visual source supports 627x627 PNG or 1254x1254 2x2 sheets; runtime display is category-constrained. | K12: Readable map marker.
A13: ☐ | B13: missing_bg | C13: placeholders/missing_bg.png | D13: Simple colorful fallback scene background. | E13: P0 fallback | F13: 627x627 PNG source | G13: HUD/button 24-48px; inventory 32-64px; reward/shop card 64-96px; modal 96-128px | H13: Static fallback | I13: placeholders/ | J13: Fullscreen fallback not 627-only. | Updated 2026-05-19: non-board visual source supports 627x627 PNG or 1254x1254 2x2 sheets; runtime display is category-constrained. | K13: Colorful non-distracting backdrop.

Sheet 08 BG - Scenes
A1: 8. Background Assets — Scenes
A2: Tracking sheet generated from the uploaded markdown. Done? is unchecked by default.
A4: Done? | B4: Asset Key | C4: Suggested Folder | D4: Designer Description | E4: Priority | F4: Source / Export Size | G4: Runtime Render Size | H4: Exact Frames / Count | I4: Final Folder Structure (relative to public/assets) | J4: Audit / Release Note | K4: GDD Theme / Prompt Note
A5: ☐ | B5: bg_scene_title_festival | C5: backgrounds/scenes/ | D5: Title screen image showing Brixonia festival, falling stars, and playful blocks. | E5: P0 | F5: Portrait background 720x1280 or 1080x1920 PNG; 627x627 only for thumbnails | G5: cover/contain portrait frame; do not force into icon rules | H5: Static/layered; parallax variants as needed | I5: backgrounds/ | J5: Audit: replace placeholder backgrounds on critical path. | Updated 2026-05-19: non-board visual source supports 627x627 PNG or 1254x1254 2x2 sheets; runtime display is category-constrained. | K5: Stage-themed cheerful festival dungeon backdrop.
A6: ☐ | B6: bg_scene_main_menu | C6: backgrounds/scenes/ | D6: Main menu scene with cozy arcade-festival framing. | E6: P0 | F6: Portrait background 720x1280 or 1080x1920 PNG; 627x627 only for thumbnails | G6: cover/contain portrait frame; do not force into icon rules | H6: Static/layered; parallax variants as needed | I6: backgrounds/ | J6: Audit: replace placeholder backgrounds on critical path. | Updated 2026-05-19: non-board visual source supports 627x627 PNG or 1254x1254 2x2 sheets; runtime display is category-constrained. | K6: Stage-themed cheerful festival dungeon backdrop.
A7: ☐ | B7: bg_scene_hub_brixonia | C7: backgrounds/scenes/ | D7: Festival hub overview with booths, lanterns, and colorful magical mess. | E7: P1 | F7: Portrait background 720x1280 or 1080x1920 PNG; 627x627 only for thumbnails | G7: cover/contain portrait frame; do not force into icon rules | H7: Static/layered; parallax variants as needed | I7: backgrounds/ | J7: Audit: replace placeholder backgrounds on critical path. | Updated 2026-05-19: non-board visual source supports 627x627 PNG or 1254x1254 2x2 sheets; runtime display is category-constrained. | K7: Stage-themed cheerful festival dungeon backdrop.
A8: ☐ | B8: bg_scene_hero_select | C8: backgrounds/scenes/ | D8: Hero select backdrop with stage or festival booth silhouettes. | E8: P1 | F8: Portrait background 720x1280 or 1080x1920 PNG; 627x627 only for thumbnails | G8: cover/contain portrait frame; do not force into icon rules | H8: Static/layered; parallax variants as needed | I8: backgrounds/ | J8: Audit: replace placeholder backgrounds on critical path. | Updated 2026-05-19: non-board visual source supports 627x627 PNG or 1254x1254 2x2 sheets; runtime display is category-constrained. | K8: Stage-themed cheerful festival dungeon backdrop.
A9: ☐ | B9: bg_scene_tutorial | C9: backgrounds/scenes/ | D9: Simple classroom/festival demo area for learning controls. | E9: P1 | F9: Portrait background 720x1280 or 1080x1920 PNG; 627x627 only for thumbnails | G9: cover/contain portrait frame; do not force into icon rules | H9: Static/layered; parallax variants as needed | I9: backgrounds/ | J9: Audit: replace placeholder backgrounds on critical path. | Updated 2026-05-19: non-board visual source supports 627x627 PNG or 1254x1254 2x2 sheets; runtime display is category-constrained. | K9: Stage-themed cheerful festival dungeon backdrop.
A10: ☐ | B10: bg_scene_reward | C10: backgrounds/scenes/ | D10: Reward backdrop with sparkles, cards, and treasure glow. | E10: P0 | F10: Portrait background 720x1280 or 1080x1920 PNG; 627x627 only for thumbnails | G10: cover/contain portrait frame; do not force into icon rules | H10: Static/layered; parallax variants as needed | I10: backgrounds/ | J10: Audit: replace placeholder backgrounds on critical path. | Updated 2026-05-19: non-board visual source supports 627x627 PNG or 1254x1254 2x2 sheets; runtime display is category-constrained. | K10: Stage-themed cheerful festival dungeon backdrop.
A11: ☐ | B11: bg_scene_shop | C11: backgrounds/scenes/ | D11: Marnie’s cozy merchant stall filled with snacks and items. | E11: P0 | F11: Portrait background 720x1280 or 1080x1920 PNG; 627x627 only for thumbnails | G11: cover/contain portrait frame; do not force into icon rules | H11: Static/layered; parallax variants as needed | I11: backgrounds/ | J11: Audit: replace placeholder backgrounds on critical path. | Updated 2026-05-19: non-board visual source supports 627x627 PNG or 1254x1254 2x2 sheets; runtime display is category-constrained. | K11: Stage-themed cheerful festival dungeon backdrop.
A12: ☐ | B12: bg_scene_event | C12: backgrounds/scenes/ | D12: Generic event backdrop with flexible festival/dungeon props. | E12: P1 | F12: Portrait background 720x1280 or 1080x1920 PNG; 627x627 only for thumbnails | G12: cover/contain portrait frame; do not force into icon rules | H12: Static/layered; parallax variants as needed | I12: backgrounds/ | J12: Audit: replace placeholder backgrounds on critical path. | Updated 2026-05-19: non-board visual source supports 627x627 PNG or 1254x1254 2x2 sheets; runtime display is category-constrained. | K12: Stage-themed cheerful festival dungeon backdrop.
A13: ☐ | B13: bg_scene_rest | C13: backgrounds/scenes/ | D13: Safe rest spot with pillows, snacks, and warm lanterns. | E13: P1 | F13: Portrait background 720x1280 or 1080x1920 PNG; 627x627 only for thumbnails | G13: cover/contain portrait frame; do not force into icon rules | H13: Static/layered; parallax variants as needed | I13: backgrounds/ | J13: Audit: replace placeholder backgrounds on critical path. | Updated 2026-05-19: non-board visual source supports 627x627 PNG or 1254x1254 2x2 sheets; runtime display is category-constrained. | K13: Stage-themed cheerful festival dungeon backdrop.
A14: ☐ | B14: bg_scene_treasure | C14: backgrounds/scenes/ | D14: Treasure room with glowing chest and playful sparkles. | E14: P1 | F14: Portrait background 720x1280 or 1080x1920 PNG; 627x627 only for thumbnails | G14: cover/contain portrait frame; do not force into icon rules | H14: Static/layered; parallax variants as needed | I14: backgrounds/ | J14: Audit: replace placeholder backgrounds on critical path. | Updated 2026-05-19: non-board visual source supports 627x627 PNG or 1254x1254 2x2 sheets; runtime display is category-constrained. | K14: Stage-themed cheerful festival dungeon backdrop.
A15: ☐ | B15: bg_scene_game_over | C15: backgrounds/scenes/ | D15: Soft defeat backdrop with block pile and encouraging restart tone. | E15: P0 | F15: Portrait background 720x1280 or 1080x1920 PNG; 627x627 only for thumbnails | G15: cover/contain portrait frame; do not force into icon rules | H15: Static/layered; parallax variants as needed | I15: backgrounds/ | J15: Audit: replace placeholder backgrounds on critical path. | Updated 2026-05-19: non-board visual source supports 627x627 PNG or 1254x1254 2x2 sheets; runtime display is category-constrained. | K15: Stage-themed cheerful festival dungeon backdrop.
... A19: ☐ | B19: bg_scene_settings | C19: backgrounds/scenes/ | D19: Simple readable settings backdrop with cozy UI frame. | E19: P1 | F19: Portrait background 720x1280 or 1080x1920 PNG; 627x627 only for thumbnails | G19: cover/contain portrait frame; do not force into icon rules | H19: Static/layered; parallax variants as needed | I19: backgrounds/ | J19: Audit: replace placeholder backgrounds on critical path. | Updated 2026-05-19: non-board visual source supports 627x627 PNG or 1254x1254 2x2 sheets; runtime display is category-constrained. | K19: Stage-themed cheerful festival dungeon backdrop.

Sheet 09 BG - Stage Battle Parallax
A1: 9. Background Assets — Stage Battle Parallax
A2: Tracking sheet generated from the uploaded markdown. Done? is unchecked by default.
A4: Done? | B4: Asset Key | C4: Suggested Folder | D4: Designer Description | E4: Priority | F4: Source / Export Size | G4: Runtime Render Size | H4: Exact Frames / Count | I4: Final Folder Structure (relative to public/assets) | J4: Audit / Release Note | K4: GDD Theme / Prompt Note
A5: ☐ | B5: bg_stage_sprinkle_sewers_battle_far | C5: backgrounds/stages/ | D5: Sprinkle Sewers battle background distant parallax layer; show candy sewer with rainbow water, frosting pipes, and cupcake slime colors. | E5: P0 | F5: Portrait background 720x1280 or 1080x1920 PNG; 627x627 only for thumbnails | G5: cover/contain portrait frame; do not force into icon rules | H5: Static/layered; parallax variants as needed | I5: backgrounds/ | J5: Audit: replace placeholder backgrounds on critical path. | Updated 2026-05-19: non-board visual source supports 627x627 PNG or 1254x1254 2x2 sheets; runtime display is category-constrained. | K5: Stage-themed cheerful festival dungeon backdrop.
A6: ☐ | B6: bg_stage_sprinkle_sewers_battle_mid | C6: backgrounds/stages/ | D6: Sprinkle Sewers battle background main scenic layer; show candy sewer with rainbow water, frosting pipes, and cupcake slime colors. | E6: P0 | F6: Portrait background 720x1280 or 1080x1920 PNG; 627x627 only for thumbnails | G6: cover/contain portrait frame; do not force into icon rules | H6: Static/layered; parallax variants as needed | I6: backgrounds/ | J6: Audit: replace placeholder backgrounds on critical path. | Updated 2026-05-19: non-board visual source supports 627x627 PNG or 1254x1254 2x2 sheets; runtime display is category-constrained. | K6: Stage-themed cheerful festival dungeon backdrop.
A7: ☐ | B7: bg_stage_sprinkle_sewers_battle_near | C7: backgrounds/stages/ | D7: Sprinkle Sewers battle background foreground framing layer; show candy sewer with rainbow water, frosting pipes, and cupcake slime colors. | E7: P0 | F7: Portrait background 720x1280 or 1080x1920 PNG; 627x627 only for thumbnails | G7: cover/contain portrait frame; do not force into icon rules | H7: Static/layered; parallax variants as needed | I7: backgrounds/ | J7: Audit: replace placeholder backgrounds on critical path. | Updated 2026-05-19: non-board visual source supports 627x627 PNG or 1254x1254 2x2 sheets; runtime display is category-constrained. | K7: Stage-themed cheerful festival dungeon backdrop.
A8: ☐ | B8: bg_stage_goblin_workshop_battle_far | C8: backgrounds/stages/ | D8: Goblin Workshop battle background distant parallax layer; show goblin machinery, toy bombs, springs, gears, and warning signs. | E8: P0 | F8: Portrait background 720x1280 or 1080x1920 PNG; 627x627 only for thumbnails | G8: cover/contain portrait frame; do not force into icon rules | H8: Static/layered; parallax variants as needed | I8: backgrounds/ | J8: Audit: replace placeholder backgrounds on critical path. | Updated 2026-05-19: non-board visual source supports 627x627 PNG or 1254x1254 2x2 sheets; runtime display is category-constrained. | K8: Stage-themed cheerful festival dungeon backdrop.
A9: ☐ | B9: bg_stage_goblin_workshop_battle_mid | C9: backgrounds/stages/ | D9: Goblin Workshop battle background main scenic layer; show goblin machinery, toy bombs, springs, gears, and warning signs. | E9: P0 | F9: Portrait background 720x1280 or 1080x1920 PNG; 627x627 only for thumbnails | G9: cover/contain portrait frame; do not force into icon rules | H9: Static/layered; parallax variants as needed | I9: backgrounds/ | J9: Audit: replace placeholder backgrounds on critical path. | Updated 2026-05-19: non-board visual source supports 627x627 PNG or 1254x1254 2x2 sheets; runtime display is category-constrained. | K9: Stage-themed cheerful festival dungeon backdrop.
A10: ☐ | B10: bg_stage_goblin_workshop_battle_near | C10: backgrounds/stages/ | D10: Goblin Workshop battle background foreground framing layer; show goblin machinery, toy bombs, springs, gears, and warning signs. | E10: P0 | F10: Portrait background 720x1280 or 1080x1920 PNG; 627x627 only for thumbnails | G10: cover/contain portrait frame; do not force into icon rules | H10: Static/layered; parallax variants as needed | I10: backgrounds/ | J10: Audit: replace placeholder backgrounds on critical path. | Updated 2026-05-19: non-board visual source supports 627x627 PNG or 1254x1254 2x2 sheets; runtime display is category-constrained. | K10: Stage-themed cheerful festival dungeon backdrop.
A11: ☐ | B11: bg_stage_frosty_pantry_battle_far | C11: backgrounds/stages/ | D11: Frosty Pantry battle background distant parallax layer; show magical freezer with ice cream crates, cold mist, and slippery tiles. | E11: P1 | F11: Portrait background 720x1280 or 1080x1920 PNG; 627x627 only for thumbnails | G11: cover/contain portrait frame; do not force into icon rules | H11: Static/layered; parallax variants as needed | I11: backgrounds/ | J11: Audit: replace placeholder backgrounds on critical path. | Updated 2026-05-19: non-board visual source supports 627x627 PNG or 1254x1254 2x2 sheets; runtime display is category-constrained. | K11: Stage-themed cheerful festival dungeon backdrop.
A12: ☐ | B12: bg_stage_frosty_pantry_battle_mid | C12: backgrounds/stages/ | D12: Frosty Pantry battle background main scenic layer; show magical freezer with ice cream crates, cold mist, and slippery tiles. | E12: P1 | F12: Portrait background 720x1280 or 1080x1920 PNG; 627x627 only for thumbnails | G12: cover/contain portrait frame; do not force into icon rules | H12: Static/layered; parallax variants as needed | I12: backgrounds/ | J12: Audit: replace placeholder backgrounds on critical path. | Updated 2026-05-19: non-board visual source supports 627x627 PNG or 1254x1254 2x2 sheets; runtime display is category-constrained. | K12: Stage-themed cheerful festival dungeon backdrop.
A13: ☐ | B13: bg_stage_frosty_pantry_battle_near | C13: backgrounds/stages/ | D13: Frosty Pantry battle background foreground framing layer; show magical freezer with ice cream crates, cold mist, and slippery tiles. | E13: P1 | F13: Portrait background 720x1280 or 1080x1920 PNG; 627x627 only for thumbnails | G13: cover/contain portrait frame; do not force into icon rules | H13: Static/layered; parallax variants as needed | I13: backgrounds/ | J13: Audit: replace placeholder backgrounds on critical path. | Updated 2026-05-19: non-board visual source supports 627x627 PNG or 1254x1254 2x2 sheets; runtime display is category-constrained. | K13: Stage-themed cheerful festival dungeon backdrop.
A14: ☐ | B14: bg_stage_pillow_castle_battle_far | C14: backgrounds/stages/ | D14: Pillow Castle battle background distant parallax layer; show soft pillow fortress with plush toys, blankets, and sleepy fabric shapes. | E14: P1 | F14: Portrait background 720x1280 or 1080x1920 PNG; 627x627 only for thumbnails | G14: cover/contain portrait frame; do not force into icon rules | H14: Static/layered; parallax variants as needed | I14: backgrounds/ | J14: Audit: replace placeholder backgrounds on critical path. | Updated 2026-05-19: non-board visual source supports 627x627 PNG or 1254x1254 2x2 sheets; runtime display is category-constrained. | K14: Stage-themed cheerful festival dungeon backdrop.
A15: ☐ | B15: bg_stage_pillow_castle_battle_mid | C15: backgrounds/stages/ | D15: Pillow Castle battle background main scenic layer; show soft pillow fortress with plush toys, blankets, and sleepy fabric shapes. | E15: P1 | F15: Portrait background 720x1280 or 1080x1920 PNG; 627x627 only for thumbnails | G15: cover/contain portrait frame; do not force into icon rules | H15: Static/layered; parallax variants as needed | I15: backgrounds/ | J15: Audit: replace placeholder backgrounds on critical path. | Updated 2026-05-19: non-board visual source supports 627x627 PNG or 1254x1254 2x2 sheets; runtime display is category-constrained. | K15: Stage-themed cheerful festival dungeon backdrop.
... A22: ☐ | B22: bg_stage_bloxley_block_palace_battle_near | C22: backgrounds/stages/ | D22: Bloxley’s Block Palace battle background foreground framing layer; show royal block palace with square banners, confetti cannons, and toy flags. | E22: P1 | F22: Portrait background 720x1280 or 1080x1920 PNG; 627x627 only for thumbnails | G22: cover/contain portrait frame; do not force into icon rules | H22: Static/layered; parallax variants as needed | I22: backgrounds/ | J22: Audit: replace placeholder backgrounds on critical path. | Updated 2026-05-19: non-board visual source supports 627x627 PNG or 1254x1254 2x2 sheets; runtime display is category-constrained. | K22: Stage-themed cheerful festival dungeon backdrop.

Sheet 10 BG - Boss Arenas
A1: 10. Background Assets — Boss Arenas
A2: Tracking sheet generated from the uploaded markdown. Done? is unchecked by default.
A4: Done? | B4: Asset Key | C4: Suggested Folder | D4: Designer Description | E4: Priority | F4: Source / Export Size | G4: Runtime Render Size | H4: Exact Frames / Count | I4: Final Folder Structure (relative to public/assets) | J4: Audit / Release Note | K4: GDD Theme / Prompt Note
A5: ☐ | B5: bg_boss_cupcake_slime_king_arena | C5: backgrounds/stages/ | D5: Boss-specific arena for Cupcake Slime King: sticky candy sewer boss arena with frosting puddles and giant cupcake slime throne. | E5: P1 | F5: Portrait background 720x1280 or 1080x1920 PNG; 627x627 only for thumbnails | G5: cover/contain portrait frame; do not force into icon rules | H5: Static/layered; parallax variants as needed | I5: backgrounds/ | J5: Audit: replace placeholder backgrounds on critical path. | Updated 2026-05-19: non-board visual source supports 627x627 PNG or 1254x1254 2x2 sheets; runtime display is category-constrained. | K5: Stage-themed cheerful festival dungeon backdrop.
A6: ☐ | B6: bg_boss_prototype_no_7_arena | C6: backgrounds/stages/ | D6: Boss-specific arena for Prototype No. 7: malfunctioning workshop arena with safe-looking machines and bomb props. | E6: P1 | F6: Portrait background 720x1280 or 1080x1920 PNG; 627x627 only for thumbnails | G6: cover/contain portrait frame; do not force into icon rules | H6: Static/layered; parallax variants as needed | I6: backgrounds/ | J6: Audit: replace placeholder backgrounds on critical path. | Updated 2026-05-19: non-board visual source supports 627x627 PNG or 1254x1254 2x2 sheets; runtime display is category-constrained. | K6: Stage-themed cheerful festival dungeon backdrop.
A7: ☐ | B7: bg_boss_gelato_golem_arena | C7: backgrounds/stages/ | D7: Boss-specific arena for Gelato Golem: freezer boss arena with melting rainbow gelato and ice platforms. | E7: P1 | F7: Portrait background 720x1280 or 1080x1920 PNG; 627x627 only for thumbnails | G7: cover/contain portrait frame; do not force into icon rules | H7: Static/layered; parallax variants as needed | I7: backgrounds/ | J7: Audit: replace placeholder backgrounds on critical path. | Updated 2026-05-19: non-board visual source supports 627x627 PNG or 1254x1254 2x2 sheets; runtime display is category-constrained. | K7: Stage-themed cheerful festival dungeon backdrop.
A8: ☐ | B8: bg_boss_sir_snore_a_lot_arena | C8: backgrounds/stages/ | D8: Boss-specific arena for Sir Snore-a-Lot: pillow castle boss arena with blanket banners and sleepy toy shields. | E8: P1 | F8: Portrait background 720x1280 or 1080x1920 PNG; 627x627 only for thumbnails | G8: cover/contain portrait frame; do not force into icon rules | H8: Static/layered; parallax variants as needed | I8: backgrounds/ | J8: Audit: replace placeholder backgrounds on critical path. | Updated 2026-05-19: non-board visual source supports 627x627 PNG or 1254x1254 2x2 sheets; runtime display is category-constrained. | K8: Stage-themed cheerful festival dungeon backdrop.
A9: ☐ | B9: bg_boss_high_score_hydra_arena | C9: backgrounds/stages/ | D9: Boss-specific arena for High Score Hydra: arcade boss arena with scoreboard, neon combo lights, and hydra cabinet energy. | E9: P1 | F9: Portrait background 720x1280 or 1080x1920 PNG; 627x627 only for thumbnails | G9: cover/contain portrait frame; do not force into icon rules | H9: Static/layered; parallax variants as needed | I9: backgrounds/ | J9: Audit: replace placeholder backgrounds on critical path. | Updated 2026-05-19: non-board visual source supports 627x627 PNG or 1254x1254 2x2 sheets; runtime display is category-constrained. | K9: Stage-themed cheerful festival dungeon backdrop.
A10: ☐ | B10: bg_boss_king_bloxley_arena | C10: backgrounds/stages/ | D10: Boss-specific arena for King Bloxley: final royal block throne room with symmetry marks and confetti cannons. | E10: P1 | F10: Portrait background 720x1280 or 1080x1920 PNG; 627x627 only for thumbnails | G10: cover/contain portrait frame; do not force into icon rules | H10: Static/layered; parallax variants as needed | I10: backgrounds/ | J10: Audit: replace placeholder backgrounds on critical path. | Updated 2026-05-19: non-board visual source supports 627x627 PNG or 1254x1254 2x2 sheets; runtime display is category-constrained. | K10: Stage-themed cheerful festival dungeon backdrop.

Sheet 11 Map - Map BGs
A1: 11. Map Assets — Map Backgrounds
A2: Tracking sheet generated from the uploaded markdown. Done? is unchecked by default.
A4: Done? | B4: Asset Key | C4: Suggested Folder | D4: Designer Description | E4: Priority | F4: Source / Export Size | G4: Runtime Render Size | H4: Exact Frames / Count | I4: Final Folder Structure (relative to public/assets) | J4: Audit / Release Note | K4: GDD Theme / Prompt Note
A5: ☐ | B5: bg_map_sprinkle_sewers | C5: backgrounds/maps/ | D5: Roguelike map background for Sprinkle Sewers; use icons/paths over this readable stage map. | E5: P0 | F5: 627x627 PNG source for nodes/icons/routes; backgrounds use portrait size | G5: Map node 32-56px; selected node/detail 64-96px; route card 96-180px | H5: State variants as needed | I5: icons/map-nodes/ | J5: Audit: Stage 6 route node/smoke testing pending. | Updated 2026-05-19: non-board visual source supports 627x627 PNG or 1254x1254 2x2 sheets; runtime display is category-constrained. | K5: Cheerful stage-map icon; readable normal/event/shop/rest/treasure/elite/boss state.
A6: ☐ | B6: bg_map_goblin_workshop | C6: backgrounds/maps/ | D6: Roguelike map background for Goblin Workshop; use icons/paths over this readable stage map. | E6: P1 | F6: 627x627 PNG source for nodes/icons/routes; backgrounds use portrait size | G6: Map node 32-56px; selected node/detail 64-96px; route card 96-180px | H6: State variants as needed | I6: icons/map-nodes/ | J6: Audit: Stage 6 route node/smoke testing pending. | Updated 2026-05-19: non-board visual source supports 627x627 PNG or 1254x1254 2x2 sheets; runtime display is category-constrained. | K6: Cheerful stage-map icon; readable normal/event/shop/rest/treasure/elite/boss state.
A7: ☐ | B7: bg_map_frosty_pantry | C7: backgrounds/maps/ | D7: Roguelike map background for Frosty Pantry; use icons/paths over this readable stage map. | E7: P1 | F7: 627x627 PNG source for nodes/icons/routes; backgrounds use portrait size | G7: Map node 32-56px; selected node/detail 64-96px; route card 96-180px | H7: State variants as needed | I7: icons/map-nodes/ | J7: Audit: Stage 6 route node/smoke testing pending. | Updated 2026-05-19: non-board visual source supports 627x627 PNG or 1254x1254 2x2 sheets; runtime display is category-constrained. | K7: Cheerful stage-map icon; readable normal/event/shop/rest/treasure/elite/boss state.
A8: ☐ | B8: bg_map_pillow_castle | C8: backgrounds/maps/ | D8: Roguelike map background for Pillow Castle; use icons/paths over this readable stage map. | E8: P1 | F8: 627x627 PNG source for nodes/icons/routes; backgrounds use portrait size | G8: Map node 32-56px; selected node/detail 64-96px; route card 96-180px | H8: State variants as needed | I8: icons/map-nodes/ | J8: Audit: Stage 6 route node/smoke testing pending. | Updated 2026-05-19: non-board visual source supports 627x627 PNG or 1254x1254 2x2 sheets; runtime display is category-constrained. | K8: Cheerful stage-map icon; readable normal/event/shop/rest/treasure/elite/boss state.
A9: ☐ | B9: bg_map_starfall_arcade | C9: backgrounds/maps/ | D9: Roguelike map background for Starfall Arcade; use icons/paths over this readable stage map. | E9: P1 | F9: 627x627 PNG source for nodes/icons/routes; backgrounds use portrait size | G9: Map node 32-56px; selected node/detail 64-96px; route card 96-180px | H9: State variants as needed | I9: icons/map-nodes/ | J9: Audit: Stage 6 route node/smoke testing pending. | Updated 2026-05-19: non-board visual source supports 627x627 PNG or 1254x1254 2x2 sheets; runtime display is category-constrained. | K9: Cheerful stage-map icon; readable normal/event/shop/rest/treasure/elite/boss state.
A10: ☐ | B10: bg_map_bloxley_block_palace | C10: backgrounds/maps/ | D10: Roguelike map background for Bloxley’s Block Palace; use icons/paths over this readable stage map. | E10: P1 | F10: 627x627 PNG source for nodes/icons/routes; backgrounds use portrait size | G10: Map node 32-56px; selected node/detail 64-96px; route card 96-180px | H10: State variants as needed | I10: icons/map-nodes/ | J10: Audit: Stage 6 route node/smoke testing pending. | Updated 2026-05-19: non-board visual source supports 627x627 PNG or 1254x1254 2x2 sheets; runtime display is category-constrained. | K10: Cheerful stage-map icon; readable normal/event/shop/rest/treasure/elite/boss state.

Sheet 12 Map - Node States
A1: 12. Map Assets — Node States
A2: Tracking sheet generated from the uploaded markdown. Done? is unchecked by default.
A4: Done? | B4: Asset Key | C4: Suggested Folder | D4: Designer Description | E4: Priority | F4: Source / Export Size | G4: Runtime Render Size | H4: Exact Frames / Count | I4: Final Folder Structure (relative to public/assets) | J4: Audit / Release Note | K4: GDD Theme / Prompt Note
A5: ☐ | B5: map_node_start_locked | C5: map/nodes/ | D5: Start node, safe and friendly entry point. Unavailable gray/low-saturation state. Must be readable at mobile size. | E5: P0 | F5: 627x627 PNG source for nodes/icons/routes; backgrounds use portrait size | G5: Map node 32-56px; selected node/detail 64-96px; route card 96-180px | H5: State variants as needed | I5: icons/map-nodes/ | J5: Audit: Stage 6 route node/smoke testing pending. | Updated 2026-05-19: non-board visual source supports 627x627 PNG or 1254x1254 2x2 sheets; runtime display is category-constrained. | K5: Cheerful stage-map icon; readable normal/event/shop/rest/treasure/elite/boss state.
A6: ☐ | B6: map_node_start_available | C6: map/nodes/ | D6: Start node, safe and friendly entry point. Selectable glowing state. Must be readable at mobile size. | E6: P0 | F6: 627x627 PNG source for nodes/icons/routes; backgrounds use portrait size | G6: Map node 32-56px; selected node/detail 64-96px; route card 96-180px | H6: State variants as needed | I6: icons/map-nodes/ | J6: Audit: Stage 6 route node/smoke testing pending. | Updated 2026-05-19: non-board visual source supports 627x627 PNG or 1254x1254 2x2 sheets; runtime display is category-constrained. | K6: Cheerful stage-map icon; readable normal/event/shop/rest/treasure/elite/boss state.
A7: ☐ | B7: map_node_start_current | C7: map/nodes/ | D7: Start node, safe and friendly entry point. Current player position state. Must be readable at mobile size. | E7: P0 | F7: 627x627 PNG source for nodes/icons/routes; backgrounds use portrait size | G7: Map node 32-56px; selected node/detail 64-96px; route card 96-180px | H7: State variants as needed | I7: icons/map-nodes/ | J7: Audit: Stage 6 route node/smoke testing pending. | Updated 2026-05-19: non-board visual source supports 627x627 PNG or 1254x1254 2x2 sheets; runtime display is category-constrained. | K7: Cheerful stage-map icon; readable normal/event/shop/rest/treasure/elite/boss state.
A8: ☐ | B8: map_node_start_completed | C8: map/nodes/ | D8: Start node, safe and friendly entry point. Completed checked/cleared state. Must be readable at mobile size. | E8: P0 | F8: 627x627 PNG source for nodes/icons/routes; backgrounds use portrait size | G8: Map node 32-56px; selected node/detail 64-96px; route card 96-180px | H8: State variants as needed | I8: icons/map-nodes/ | J8: Audit: Stage 6 route node/smoke testing pending. | Updated 2026-05-19: non-board visual source supports 627x627 PNG or 1254x1254 2x2 sheets; runtime display is category-constrained. | K8: Cheerful stage-map icon; readable normal/event/shop/rest/treasure/elite/boss state.
A9: ☐ | B9: map_node_normal_locked | C9: map/nodes/ | D9: Normal battle node with small monster symbol. Unavailable gray/low-saturation state. Must be readable at mobile size. | E9: P0 | F9: 627x627 PNG source for nodes/icons/routes; backgrounds use portrait size | G9: Map node 32-56px; selected node/detail 64-96px; route card 96-180px | H9: State variants as needed | I9: icons/map-nodes/ | J9: Audit: Stage 6 route node/smoke testing pending. | Updated 2026-05-19: non-board visual source supports 627x627 PNG or 1254x1254 2x2 sheets; runtime display is category-constrained. | K9: Cheerful stage-map icon; readable normal/event/shop/rest/treasure/elite/boss state.
A10: ☐ | B10: map_node_normal_available | C10: map/nodes/ | D10: Normal battle node with small monster symbol. Selectable glowing state. Must be readable at mobile size. | E10: P0 | F10: 627x627 PNG source for nodes/icons/routes; backgrounds use portrait size | G10: Map node 32-56px; selected node/detail 64-96px; route card 96-180px | H10: State variants as needed | I10: icons/map-nodes/ | J10: Audit: Stage 6 route node/smoke testing pending. | Updated 2026-05-19: non-board visual source supports 627x627 PNG or 1254x1254 2x2 sheets; runtime display is category-constrained. | K10: Cheerful stage-map icon; readable normal/event/shop/rest/treasure/elite/boss state.
A11: ☐ | B11: map_node_normal_current | C11: map/nodes/ | D11: Normal battle node with small monster symbol. Current player position state. Must be readable at mobile size. | E11: P0 | F11: 627x627 PNG source for nodes/icons/routes; backgrounds use portrait size | G11: Map node 32-56px; selected node/detail 64-96px; route card 96-180px | H11: State variants as needed | I11: icons/map-nodes/ | J11: Audit: Stage 6 route node/smoke testing pending. | Updated 2026-05-19: non-board visual source supports 627x627 PNG or 1254x1254 2x2 sheets; runtime display is category-constrained. | K11: Cheerful stage-map icon; readable normal/event/shop/rest/treasure/elite/boss state.
A12: ☐ | B12: map_node_normal_completed | C12: map/nodes/ | D12: Normal battle node with small monster symbol. Completed checked/cleared state. Must be readable at mobile size. | E12: P0 | F12: 627x627 PNG source for nodes/icons/routes; backgrounds use portrait size | G12: Map node 32-56px; selected node/detail 64-96px; route card 96-180px | H12: State variants as needed | I12: icons/map-nodes/ | J12: Audit: Stage 6 route node/smoke testing pending. | Updated 2026-05-19: non-board visual source supports 627x627 PNG or 1254x1254 2x2 sheets; runtime display is category-constrained. | K12: Cheerful stage-map icon; readable normal/event/shop/rest/treasure/elite/boss state.
A13: ☐ | B13: map_node_elite_locked | C13: map/nodes/ | D13: Elite battle node with stronger warning frame. Unavailable gray/low-saturation state. Must be readable at mobile size. | E13: P1 | F13: 627x627 PNG source for nodes/icons/routes; backgrounds use portrait size | G13: Map node 32-56px; selected node/detail 64-96px; route card 96-180px | H13: State variants as needed | I13: icons/map-nodes/ | J13: Audit: Stage 6 route node/smoke testing pending. | Updated 2026-05-19: non-board visual source supports 627x627 PNG or 1254x1254 2x2 sheets; runtime display is category-constrained. | K13: Cheerful stage-map icon; readable normal/event/shop/rest/treasure/elite/boss state.
A14: ☐ | B14: map_node_elite_available | C14: map/nodes/ | D14: Elite battle node with stronger warning frame. Selectable glowing state. Must be readable at mobile size. | E14: P1 | F14: 627x627 PNG source for nodes/icons/routes; backgrounds use portrait size | G14: Map node 32-56px; selected node/detail 64-96px; route card 96-180px | H14: State variants as needed | I14: icons/map-nodes/ | J14: Audit: Stage 6 route node/smoke testing pending. | Updated 2026-05-19: non-board visual source supports 627x627 PNG or 1254x1254 2x2 sheets; runtime display is category-constrained. | K14: Cheerful stage-map icon; readable normal/event/shop/rest/treasure/elite/boss state.
A15: ☐ | B15: map_node_elite_current | C15: map/nodes/ | D15: Elite battle node with stronger warning frame. Current player position state. Must be readable at mobile size. | E15: P1 | F15: 627x627 PNG source for nodes/icons/routes; backgrounds use portrait size | G15: Map node 32-56px; selected node/detail 64-96px; route card 96-180px | H15: State variants as needed | I15: icons/map-nodes/ | J15: Audit: Stage 6 route node/smoke testing pending. | Updated 2026-05-19: non-board visual source supports 627x627 PNG or 1254x1254 2x2 sheets; runtime display is category-constrained. | K15: Cheerful stage-map icon; readable normal/event/shop/rest/treasure/elite/boss state.
... A44: ☐ | B44: map_node_mini_boss_completed | C44: map/nodes/ | D44: Mini-boss or royal guard node before final boss. Completed checked/cleared state. Must be readable at mobile size. | E44: P1 | F44: 627x627 PNG source for nodes/icons/routes; backgrounds use portrait size | G44: Map node 32-56px; selected node/detail 64-96px; route card 96-180px | H44: State variants as needed | I44: icons/map-nodes/ | J44: Audit: Stage 6 route node/smoke testing pending. | Updated 2026-05-19: non-board visual source supports 627x627 PNG or 1254x1254 2x2 sheets; runtime display is category-constrained. | K44: Cheerful stage-map icon; readable normal/event/shop/rest/treasure/elite/boss state.

Sheet 13 Map - Paths and Decorations
A1: 13. Map Assets — Paths and Decorations
A2: Tracking sheet generated from the uploaded markdown. Done? is unchecked by default.
A4: Done? | B4: Asset Key | C4: Suggested Folder | D4: Designer Description | E4: Priority | F4: Source / Export Size | G4: Runtime Render Size | H4: Exact Frames / Count | I4: Final Folder Structure (relative to public/assets) | J4: Audit / Release Note | K4: GDD Theme / Prompt Note
A5: ☐ | B5: map_path_line_locked | C5: map/paths/ | D5: Thin muted line showing locked route connection. | E5: P0 | F5: 627x627 PNG source for nodes/icons/routes; backgrounds use portrait size | G5: Map node 32-56px; selected node/detail 64-96px; route card 96-180px | H5: State variants as needed | I5: icons/map-nodes/ | J5: Audit: Stage 6 route node/smoke testing pending. | Updated 2026-05-19: non-board visual source supports 627x627 PNG or 1254x1254 2x2 sheets; runtime display is category-constrained. | K5: Cheerful stage-map icon; readable normal/event/shop/rest/treasure/elite/boss state.
A6: ☐ | B6: map_path_line_available | C6: map/paths/ | D6: Clear readable line showing selectable route connection. | E6: P0 | F6: 627x627 PNG source for nodes/icons/routes; backgrounds use portrait size | G6: Map node 32-56px; selected node/detail 64-96px; route card 96-180px | H6: State variants as needed | I6: icons/map-nodes/ | J6: Audit: Stage 6 route node/smoke testing pending. | Updated 2026-05-19: non-board visual source supports 627x627 PNG or 1254x1254 2x2 sheets; runtime display is category-constrained. | K6: Cheerful stage-map icon; readable normal/event/shop/rest/treasure/elite/boss state.
A7: ☐ | B7: map_path_line_completed | C7: map/paths/ | D7: Route line showing already traveled path. | E7: P0 | F7: 627x627 PNG source for nodes/icons/routes; backgrounds use portrait size | G7: Map node 32-56px; selected node/detail 64-96px; route card 96-180px | H7: State variants as needed | I7: icons/map-nodes/ | J7: Audit: Stage 6 route node/smoke testing pending. | Updated 2026-05-19: non-board visual source supports 627x627 PNG or 1254x1254 2x2 sheets; runtime display is category-constrained. | K7: Cheerful stage-map icon; readable normal/event/shop/rest/treasure/elite/boss state.
A8: ☐ | B8: map_path_dotted_locked | C8: map/paths/ | D8: Optional dotted locked route style for alternate branches. | E8: P1 | F8: 627x627 PNG source for nodes/icons/routes; backgrounds use portrait size | G8: Map node 32-56px; selected node/detail 64-96px; route card 96-180px | H8: State variants as needed | I8: icons/map-nodes/ | J8: Audit: Stage 6 route node/smoke testing pending. | Updated 2026-05-19: non-board visual source supports 627x627 PNG or 1254x1254 2x2 sheets; runtime display is category-constrained. | K8: Cheerful stage-map icon; readable normal/event/shop/rest/treasure/elite/boss state.
A9: ☐ | B9: map_path_glow_available | C9: map/paths/ | D9: Glowing route overlay for newly opened path. | E9: P1 | F9: 627x627 PNG source for nodes/icons/routes; backgrounds use portrait size | G9: Map node 32-56px; selected node/detail 64-96px; route card 96-180px | H9: State variants as needed | I9: icons/map-nodes/ | J9: Audit: Stage 6 route node/smoke testing pending. | Updated 2026-05-19: non-board visual source supports 627x627 PNG or 1254x1254 2x2 sheets; runtime display is category-constrained. | K9: Cheerful stage-map icon; readable normal/event/shop/rest/treasure/elite/boss state.
A10: ☐ | B10: map_deco_sprinkle_sewers_cupcake_pipe | C10: map/decorations/ | D10: Small cupcake/frosting pipe decoration for Stage 1 map. | E10: P2 | F10: 627x627 PNG source for nodes/icons/routes; backgrounds use portrait size | G10: Map node 32-56px; selected node/detail 64-96px; route card 96-180px | H10: State variants as needed | I10: icons/map-nodes/ | J10: Audit: Stage 6 route node/smoke testing pending. | Updated 2026-05-19: non-board visual source supports 627x627 PNG or 1254x1254 2x2 sheets; runtime display is category-constrained. | K10: Cheerful stage-map icon; readable normal/event/shop/rest/treasure/elite/boss state.
A11: ☐ | B11: map_deco_goblin_workshop_gear | C11: map/decorations/ | D11: Small gear/spring decoration for Stage 2 map. | E11: P2 | F11: 627x627 PNG source for nodes/icons/routes; backgrounds use portrait size | G11: Map node 32-56px; selected node/detail 64-96px; route card 96-180px | H11: State variants as needed | I11: icons/map-nodes/ | J11: Audit: Stage 6 route node/smoke testing pending. | Updated 2026-05-19: non-board visual source supports 627x627 PNG or 1254x1254 2x2 sheets; runtime display is category-constrained. | K11: Cheerful stage-map icon; readable normal/event/shop/rest/treasure/elite/boss state.
A12: ☐ | B12: map_deco_frosty_pantry_ice_crate | C12: map/decorations/ | D12: Ice cream crate decoration for Stage 3 map. | E12: P2 | F12: 627x627 PNG source for nodes/icons/routes; backgrounds use portrait size | G12: Map node 32-56px; selected node/detail 64-96px; route card 96-180px | H12: State variants as needed | I12: icons/map-nodes/ | J12: Audit: Stage 6 route node/smoke testing pending. | Updated 2026-05-19: non-board visual source supports 627x627 PNG or 1254x1254 2x2 sheets; runtime display is category-constrained. | K12: Cheerful stage-map icon; readable normal/event/shop/rest/treasure/elite/boss state.
A13: ☐ | B13: map_deco_pillow_castle_blanket_flag | C13: map/decorations/ | D13: Blanket flag decoration for Stage 4 map. | E13: P2 | F13: 627x627 PNG source for nodes/icons/routes; backgrounds use portrait size | G13: Map node 32-56px; selected node/detail 64-96px; route card 96-180px | H13: State variants as needed | I13: icons/map-nodes/ | J13: Audit: Stage 6 route node/smoke testing pending. | Updated 2026-05-19: non-board visual source supports 627x627 PNG or 1254x1254 2x2 sheets; runtime display is category-constrained. | K13: Cheerful stage-map icon; readable normal/event/shop/rest/treasure/elite/boss state.
A14: ☐ | B14: map_deco_starfall_arcade_neon_sign | C14: map/decorations/ | D14: Neon sign decoration for Stage 5 map. | E14: P2 | F14: 627x627 PNG source for nodes/icons/routes; backgrounds use portrait size | G14: Map node 32-56px; selected node/detail 64-96px; route card 96-180px | H14: State variants as needed | I14: icons/map-nodes/ | J14: Audit: Stage 6 route node/smoke testing pending. | Updated 2026-05-19: non-board visual source supports 627x627 PNG or 1254x1254 2x2 sheets; runtime display is category-constrained. | K14: Cheerful stage-map icon; readable normal/event/shop/rest/treasure/elite/boss state.
A15: ☐ | B15: map_deco_bloxley_block_palace_royal_seal | C15: map/decorations/ | D15: Royal seal decoration for Stage 6 map. | E15: P2 | F15: 627x627 PNG source for nodes/icons/routes; backgrounds use portrait size | G15: Map node 32-56px; selected node/detail 64-96px; route card 96-180px | H15: State variants as needed | I15: icons/map-nodes/ | J15: Audit: Stage 6 route node/smoke testing pending. | Updated 2026-05-19: non-board visual source supports 627x627 PNG or 1254x1254 2x2 sheets; runtime display is category-constrained. | K15: Cheerful stage-map icon; readable normal/event/shop/rest/treasure/elite/boss state.

Sheet 14 - Heroes
A1: 14. Sprite Assets — Playable Heroes
A2: Tracking sheet generated from the uploaded markdown. Done? is unchecked by default.
A4: Done? | B4: Asset Key | C4: Suggested Folder | D4: Designer Description | E4: Priority | F4: Source / Export Size | G4: Runtime Render Size | H4: Exact Frames / Count | I4: Final Folder Structure (relative to public/assets) | J4: Audit / Release Note | K4: GDD Theme / Prompt Note
A5: ☐ | B5: spr_hero_milo_blockmancer_idle | C5: sprites/heroes/ | D5: Milo: Neutral battle idle; loopable and readable in top battle panel. Character direction: balanced starter Blockmancer, optimistic apprentice with lemonade-assistant charm. | E5: P0 | F5: 1254x1254 2x2 pose sheet (627x627 per frame); optional exact frames 627x627 | G5: Battle max 72-96px; hero select 128-180px; modal/unlock 160-220px; preserve aspect ratio | H5: Hero standard: idle 4, cast_spell 6, hit 3, victory 5, defeat_tired 4, portrait_icon 1 | I5: sprites/heroes/hero_milo_blockmancer/idle/ | J5: Audit: 8 heroes exist; Release 1 route coverage is 6 heroes. Critical heroes need final sprites. | Updated 2026-05-19: non-board visual source supports 627x627 PNG or 1254x1254 2x2 sheets; runtime display is category-constrained. | K5: Cute chibi festival adventurer, bright 32-bit style, clear top battle panel silhouette.
A6: ☐ | B6: spr_hero_milo_blockmancer_cast | C6: sprites/heroes/ | D6: Milo: Spell-casting pose with clear silhouette and hand/wand motion. Character direction: balanced starter Blockmancer, optimistic apprentice with lemonade-assistant charm. | E6: P0 | F6: 1254x1254 2x2 pose sheet (627x627 per frame); optional exact frames 627x627 | G6: Battle max 72-96px; hero select 128-180px; modal/unlock 160-220px; preserve aspect ratio | H6: Hero standard: idle 4, cast_spell 6, hit 3, victory 5, defeat_tired 4, portrait_icon 1 | I6: sprites/heroes/hero_milo_blockmancer/cast_spell/ | J6: Audit: 8 heroes exist; Release 1 route coverage is 6 heroes. Critical heroes need final sprites. | Updated 2026-05-19: non-board visual source supports 627x627 PNG or 1254x1254 2x2 sheets; runtime display is category-constrained. | K6: Cute chibi festival adventurer, bright 32-bit style, clear top battle panel silhouette.
A7: ☐ | B7: spr_hero_milo_blockmancer_attack | C7: sprites/heroes/ | D7: Milo: Quick attack pose for line-clear damage feedback. Character direction: balanced starter Blockmancer, optimistic apprentice with lemonade-assistant charm. | E7: P0 | F7: 1254x1254 2x2 pose sheet (627x627 per frame); optional exact frames 627x627 | G7: Battle max 72-96px; hero select 128-180px; modal/unlock 160-220px; preserve aspect ratio | H7: Hero standard: idle 4, cast_spell 6, hit 3, victory 5, defeat_tired 4, portrait_icon 1 | I7: sprites/heroes/hero_milo_blockmancer/attack_or_cast_spell/ | J7: Audit: 8 heroes exist; Release 1 route coverage is 6 heroes. Critical heroes need final sprites. | Updated 2026-05-19: non-board visual source supports 627x627 PNG or 1254x1254 2x2 sheets; runtime display is category-constrained. | K7: Cute chibi festival adventurer, bright 32-bit style, clear top battle panel silhouette.
A8: ☐ | B8: spr_hero_milo_blockmancer_hit | C8: sprites/heroes/ | D8: Milo: Short hurt/flinch pose, cute but readable. Character direction: balanced starter Blockmancer, optimistic apprentice with lemonade-assistant charm. | E8: P0 | F8: 1254x1254 2x2 pose sheet (627x627 per frame); optional exact frames 627x627 | G8: Battle max 72-96px; hero select 128-180px; modal/unlock 160-220px; preserve aspect ratio | H8: Hero standard: idle 4, cast_spell 6, hit 3, victory 5, defeat_tired 4, portrait_icon 1 | I8: sprites/heroes/hero_milo_blockmancer/hit/ | J8: Audit: 8 heroes exist; Release 1 route coverage is 6 heroes. Critical heroes need final sprites. | Updated 2026-05-19: non-board visual source supports 627x627 PNG or 1254x1254 2x2 sheets; runtime display is category-constrained. | K8: Cute chibi festival adventurer, bright 32-bit style, clear top battle panel silhouette.
A9: ☐ | B9: spr_hero_milo_blockmancer_victory | C9: sprites/heroes/ | D9: Milo: Celebration pose for room clear and hero select preview. Character direction: balanced starter Blockmancer, optimistic apprentice with lemonade-assistant charm. | E9: P0 | F9: 1254x1254 2x2 pose sheet (627x627 per frame); optional exact frames 627x627 | G9: Battle max 72-96px; hero select 128-180px; modal/unlock 160-220px; preserve aspect ratio | H9: Hero standard: idle 4, cast_spell 6, hit 3, victory 5, defeat_tired 4, portrait_icon 1 | I9: sprites/heroes/hero_milo_blockmancer/victory/ | J9: Audit: 8 heroes exist; Release 1 route coverage is 6 heroes. Critical heroes need final sprites. | Updated 2026-05-19: non-board visual source supports 627x627 PNG or 1254x1254 2x2 sheets; runtime display is category-constrained. | K9: Cute chibi festival adventurer, bright 32-bit style, clear top battle panel silhouette.
A10: ☐ | B10: spr_hero_milo_blockmancer_defeat | C10: sprites/heroes/ | D10: Milo: Soft defeat/tired pose without grim tone. Character direction: balanced starter Blockmancer, optimistic apprentice with lemonade-assistant charm. | E10: P0 | F10: 1254x1254 2x2 pose sheet (627x627 per frame); optional exact frames 627x627 | G10: Battle max 72-96px; hero select 128-180px; modal/unlock 160-220px; preserve aspect ratio | H10: Hero standard: idle 4, cast_spell 6, hit 3, victory 5, defeat_tired 4, portrait_icon 1 | I10: sprites/heroes/hero_milo_blockmancer/defeat_tired/ | J10: Audit: 8 heroes exist; Release 1 route coverage is 6 heroes. Critical heroes need final sprites. | Updated 2026-05-19: non-board visual source supports 627x627 PNG or 1254x1254 2x2 sheets; runtime display is category-constrained. | K10: Cute chibi festival adventurer, bright 32-bit style, clear top battle panel silhouette.
